{
  "@timestamp": "2023-06-15T09:33:04.961Z",
  "@version": "1",
  "message": "unknown error occurred",
  "host": "75a3b370a9e1",
  "path": "/backend/middleware/exceptionHandler.py",
  "tags": ["django"],
  "type": "django",
  "level": "ERROR",
  "logger_name": "backend.services.logger",
  "stack_trace": "Traceback (most recent call last):\n  File \"/usr/local/lib/python3.10/site-packages/django/core/handlers/base.py\", line 197, in _get_response\n    response = wrapped_callback(request, *callback_args, **callback_kwargs)\n  File \"/usr/local/lib/python3.10/site-packages/django/views/decorators/csrf.py\", line 56, in wrapper_view\n    return view_func(*args, **kwargs)\n  File \"/usr/local/lib/python3.10/site-packages/django/views/generic/base.py\", line 104, in view\n    return self.dispatch(request, *args, **kwargs)\n  File \"/usr/local/lib/python3.10/site-packages/rest_framework/views.py\", line 509, in dispatch\n    response = self.handle_exception(exc)\n  File \"/usr/local/lib/python3.10/site-packages/rest_framework/views.py\", line 469, in handle_exception\n    self.raise_uncaught_exception(exc)\n  File \"/usr/local/lib/python3.10/site-packages/rest_framework/views.py\", line 480, in raise_uncaught_exception\n    raise exc\n  File \"/usr/local/lib/python3.10/site-packages/rest_framework/views.py\", line 506, in dispatch\n    response = handler(request, *args, **kwargs)\n  File \"/usr/local/lib/python3.10/site-packages/rest_framework/decorators.py\", line 50, in handler\n    return func(*args, **kwargs)\n  File \"/backend/backend/authorization.py\", line 230, in wrapper\n    return func(request)\n  File \"/backend/backend/TDR/views.py\", line 793, in issue_drc\n    applicationId = request.data['applicationId']\nKeyError: 'applicationId'\n",
  "lineno": 31,
  "process": 213,
  "thread_name": "MainThread"
}
